<?xml version="1.0"?>
<robot xmlns:xacro="http://ros.org/wiki/xacro" name="my_bot">

  <!-- Base Link -->
  <link name="base_link">
    <visual>
      <geometry>
        <box size="0.4 0.3 0.1"/>
      </geometry>
      <material name="gray">
        <color rgba="0.6 0.6 0.6 1.0"/>
      </material>
    </visual>
    <collision>
      <geometry>
        <box size="0.4 0.3 0.1"/>
      </geometry>
    </collision>
    <inertial>
      <mass value="1.0"/>
      <inertia ixx="0.01" ixy="0.0" ixz="0.0"
               iyy="0.01" iyz="0.0"
               izz="0.02"/>
    </inertial>
  </link>

<!-- 초음파 센서가 달리는 링크 -->
  <link name="ultrasonic_link">
    <visual>
      <origin xyz="0 0 0.05" rpy="0 0 0"/>
      <geometry>
        <cylinder radius="0.015" length="0.05"/>
      </geometry>
      <material name="gray">
        <color rgba="0.5 0.5 0.5 1.0"/>
      </material>
    </visual>
  </link>

  <!-- Left Wheel -->
  <link name="left_wheel">
    <visual>
      <geometry>
        <cylinder radius="0.05" length="0.02"/>
      </geometry>
      <origin xyz="0 0 0" rpy="1.5708 0 0"/>
      <material name="black">
        <color rgba="0 0 0 1.0"/>
      </material>
    </visual>
    <collision>
      <geometry>
        <cylinder radius="0.05" length="0.02"/>
      </geometry>
      <origin xyz="0 0 0" rpy="1.5708 0 0"/>
    </collision>
    <inertial>
      <mass value="0.2"/>
      <inertia ixx="0.001" ixy="0.0" ixz="0.0"
               iyy="0.001" iyz="0.0"
               izz="0.001"/>
    </inertial>
  </link>

  <!-- Right Wheel -->
  <link name="right_wheel">
    <visual>
      <geometry>
        <cylinder radius="0.05" length="0.02"/>
      </geometry>
      <origin xyz="0 0 0" rpy="1.5708 0 0"/>
      <material name="black">
        <color rgba="0 0 0 1.0"/>
      </material>
    </visual>
    <collision>
      <geometry>
        <cylinder radius="0.05" length="0.02"/>
      </geometry>
      <origin xyz="0 0 0" rpy="1.5708 0 0"/>
    </collision>
    <inertial>
      <mass value="0.2"/>
      <inertia ixx="0.001" ixy="0.0" ixz="0.0"
               iyy="0.001" iyz="0.0"
               izz="0.001"/>
    </inertial>
  </link>

  <!-- 초음파 센서 링크를 base_link에 고정 -->
  <joint name="ultrasonic_joint" type="fixed">
    <parent link="base_link"/>
    <child link="ultrasonic_link"/>
    <origin xyz="0.15 0 0.05" rpy="0 0 0"/>
  </joint>

  <!-- Left Wheel Joint -->
  <joint name="left_wheel_joint" type="continuous">
    <parent link="base_link"/>
    <child link="left_wheel"/>
    <origin xyz="0 0.15 0" rpy="0 0 0"/>
    <axis xyz="0 1 0"/>
  </joint>

  <!-- Right Wheel Joint -->
  <joint name="right_wheel_joint" type="continuous">
    <parent link="base_link"/>
    <child link="right_wheel"/>
    <origin xyz="0 -0.15 0" rpy="0 0 0"/>
    <axis xyz="0 1 0"/>
  </joint>

  <!-- Gazebo Plugins -->

  <!-- 1. Gazebo ROS Node 플러그인: ROS2와 연결 -->
  <gazebo reference="base_link">
    <plugin name="gazebo_ros_node" filename="libgazebo_ros_init.so">
      <ros>
        <namespace>/</namespace>
      </ros>
    </plugin>
  </gazebo>

  <!-- 2. Diff Drive 플러그인: 이동 기능 -->
  <gazebo>
    <plugin name="diff_drive_controller" filename="libgazebo_ros_diff_drive.so">
      <ros>
        <namespace>/</namespace>
      </ros>
      <update_rate>50.0</update_rate>
      <left_joint>left_wheel_joint</left_joint>
      <right_joint>right_wheel_joint</right_joint>
      <wheel_separation>0.3</wheel_separation>
      <wheel_diameter>0.1</wheel_diameter> 
      <command_topic>cmd_vel</command_topic>
      <odometry_topic>odom</odometry_topic>
      <odometry_frame>odom</odometry_frame>
      <robot_base_frame>base_link</robot_base_frame>
      <publish_odom>true</publish_odom>
    </plugin>
  </gazebo>

    <!-- Gazebo 시뮬레이션을 위한 초음파 센서 정의 -->
  <gazebo reference="ultrasonic_link">
    <sensor type="ray" name="ultrasonic_sensor">
      <update_rate>30</update_rate>
      <pose>0 0 0 0 0 0</pose>

      <ray>
        <scan>
          <horizontal>
            <samples>1</samples>
            <resolution>1</resolution>
            <min_angle>0.0</min_angle>
            <max_angle>0.0</max_angle>
          </horizontal>
        </scan>
        <range>
          <min>0.02</min>
          <max>2.0</max>
          <resolution>0.01</resolution>
        </range>
      </ray>
      <plugin name="ultrasonic_plugin" filename="libgazebo_ros_ray_sensor.so">
        <ros>
          <namespace>/</namespace>
          <remapping>~/out:=ultrasonic</remapping>
        </ros>
        <output_type>sensor_msgs/LaserScan</output_type>
        <frame_name>ultrasonic_link</frame_name> 
      </plugin>
    </sensor>
  </gazebo>

</robot>
